Workbook
Name Slicer_Branch_Name: #N/A
Name Slicer_Category: #N/A
Name Slicer_Dining_Type: #N/A

Sheet Order_Details
A1: Detail_ID | B1: Order_ID | C1: Item_ID | D1: Quantity | E1: Sales_Amount | F1: Month | G1: Year
A2: D001 | B2: 1001 | C2: M01 | D2: 1 | E2: 250 | F2: Jan | G2: 2026
A3: D002 | B3: 1001 | C3: M02 | D3: 2 | E3: 700 | F3: Jan | G3: 2026
A4: D003 | B4: 1002 | C4: M02 | D4: 1 | E4: 350 | F4: Jan | G4: 2026
A5: D004 | B5: 1002 | C5: M03 | D5: 2 | E5: 560 | F5: Jan | G5: 2026
A6: D005 | B6: 1002 | C6: M04 | D6: 3 | E6: 1350 | F6: Jan | G6: 2026
A7: D006 | B7: 1003 | C7: M03 | D7: 1 | E7: 280 | F7: Jan | G7: 2026 | I7: TASK - 1 | K7: TASK - 2 | L7: TASK - 3 | M7: TASK - 4 | N7: Task - 5 | O7: Task - 6 | P7: Task - 7 | Q7: Task - 8
A8: D007 | B8: 1003 | C8: M04 | D8: 2 | E8: 900 | F8: Jan | G8: 2026
A9: D008 | B9: 1004 | C9: M04 | D9: 1 | E9: 450 | F9: Jan | G9: 2026 | I9: Total Unique Orders | J9: Total orders | K9: Total sales amount | L9: Total Quntity sold | M9: Item_Name By Item_ID | N9: Branch_Name BY Branch_Id | O9: Waiter_Name BY Waiter_Id | P9: Sales_Category | Q9: Classify_Orders
A10: D009 | B10: 1004 | C10: M05 | D10: 2 | E10: 360 | F10: Jan | G10: 2026 | I10: =COUNTA(_xlfn.UNIQUE(B$2:B251)) -> 100 | J10: =COUNT(Table1[Order_ID]) -> 250 | K10: =SUM(Table1[Sales_Amount]) -> 90450 | L10: =SUM(Table1[[#All],[Quantity]]) -> 450 | M10: =_xlfn.XLOOKUP(C2,Menu_Items!$A$2:$A$21,Menu_Items!$B$2:$B$21,"Not Found") -> Veg Biryani | N10: =_xlfn.XLOOKUP(Orders!D2,Branches!$A$2:$A$6,Branches!$B$2:$B$6,FALSE) -> Paradise Restaurant | O10: =_xlfn.XLOOKUP(Orders!E2,Waiters!$A$2:$A$11,Waiters!$B$2:$B$11,FALSE) -> Mahesh | P10: =IF(E2>=1000,"High_Sales","Normal_Sales") -> Normal_Sales | Q10: =IF(Orders!G2>=500,"Premium","Regular") -> Regular
A11: D010 | B11: 1004 | C11: M06 | D11: 3 | E11: 360 | F11: Jan | G11: 2026 | M11: =_xlfn.XLOOKUP(C3,Menu_Items!$A$2:$A$21,Menu_Items!$B$2:$B$21,"Not Found") -> Chicken Biryani | N11: =_xlfn.XLOOKUP(Orders!D3,Branches!$A$2:$A$6,Branches!$B$2:$B$6,FALSE) -> Spice Hub | O11: =_xlfn.XLOOKUP(Orders!E3,Waiters!$A$2:$A$11,Waiters!$B$2:$B$11,FALSE) -> Kiran | P11: =IF(E3>=1000,"High_Sales","Normal_Sales") -> Normal_Sales | Q11: =IF(Orders!G3>=500,"Premium","Regular") -> Premium
A12: D011 | B12: 1005 | C12: M05 | D12: 1 | E12: 180 | F12: Jan | G12: 2026 | M12: =_xlfn.XLOOKUP(C4,Menu_Items!$A$2:$A$21,Menu_Items!$B$2:$B$21,"Not Found") -> Chicken Biryani | N12: =_xlfn.XLOOKUP(Orders!D4,Branches!$A$2:$A$6,Branches!$B$2:$B$6,FALSE) -> Food Fiesta | O12: =_xlfn.XLOOKUP(Orders!E4,Waiters!$A$2:$A$11,Waiters!$B$2:$B$11,FALSE) -> Ramesh | P12: =IF(E4>=1000,"High_Sales","Normal_Sales") -> Normal_Sales | Q12: =IF(Orders!G4>=500,"Premium","Regular") -> Premium
A13: D012 | B13: 1005 | C13: M06 | D13: 2 | E13: 240 | F13: Jan | G13: 2026 | M13: =_xlfn.XLOOKUP(C5,Menu_Items!$A$2:$A$21,Menu_Items!$B$2:$B$21,"Not Found") -> Paneer Butter Masala | N13: =_xlfn.XLOOKUP(Orders!D5,Branches!$A$2:$A$6,Branches!$B$2:$B$6,FALSE) -> Royal Dine | O13: =_xlfn.XLOOKUP(Orders!E5,Waiters!$A$2:$A$11,Waiters!$B$2:$B$11,FALSE) -> Praveen | P13: =IF(E5>=1000,"High_Sales","Normal_Sales") -> Normal_Sales | Q13: =IF(Orders!G5>=500,"Premium","Regular") -> Premium
A14: D013 | B14: 1006 | C14: M06 | D14: 1 | E14: 120 | F14: Jan | G14: 2026 | M14: =_xlfn.XLOOKUP(C6,Menu_Items!$A$2:$A$21,Menu_Items!$B$2:$B$21,"Not Found") -> Pizza | N14: =_xlfn.XLOOKUP(Orders!D6,Branches!$A$2:$A$6,Branches!$B$2:$B$6,FALSE) -> Urban Kitchen | O14: =_xlfn.XLOOKUP(Orders!E6,Waiters!$A$2:$A$11,Waiters!$B$2:$B$11,FALSE) -> Suresh | P14: =IF(E6>=1000,"High_Sales","Normal_Sales") -> High_Sales | Q14: =IF(Orders!G6>=500,"Premium","Regular") -> Premium
A15: D014 | B15: 1006 | C15: M07 | D15: 2 | E15: 440 | F15: Jan | G15: 2026 | M15: =_xlfn.XLOOKUP(C7,Menu_Items!$A$2:$A$21,Menu_Items!$B$2:$B$21,"Not Found") -> Paneer Butter Masala | N15: =_xlfn.XLOOKUP(Orders!D7,Branches!$A$2:$A$6,Branches!$B$2:$B$6,FALSE) -> Paradise Restaurant | O15: =_xlfn.XLOOKUP(Orders!E7,Waiters!$A$2:$A$11,Waiters!$B$2:$B$11,FALSE) -> Naveen | P15: =IF(E7>=1000,"High_Sales","Normal_Sales") -> Normal_Sales | Q15: =IF(Orders!G7>=500,"Premium","Regular") -> Premium
A16: D015 | B16: 1006 | C16: M08 | D16: 3 | E16: 720 | F16: Feb | G16: 2026 | M16: =_xlfn.XLOOKUP(C8,Menu_Items!$A$2:$A$21,Menu_Items!$B$2:$B$21,"Not Found") -> Pizza | N16: =_xlfn.XLOOKUP(Orders!D8,Branches!$A$2:$A$6,Branches!$B$2:$B$6,FALSE) -> Spice Hub | O16: =_xlfn.XLOOKUP(Orders!E8,Waiters!$A$2:$A$11,Waiters!$B$2:$B$11,FALSE) -> Ajay | P16: =IF(E8>=1000,"High_Sales","Normal_Sales") -> Normal_Sales | Q16: =IF(Orders!G8>=500,"Premium","Regular") -> Premium
A17: D016 | B17: 1007 | C17: M07 | D17: 1 | E17: 220 | F17: Jan | G17: 2026 | M17: =_xlfn.XLOOKUP(C9,Menu_Items!$A$2:$A$21,Menu_Items!$B$2:$B$21,"Not Found") -> Pizza | N17: =_xlfn.XLOOKUP(Orders!D9,Branches!$A$2:$A$6,Branches!$B$2:$B$6,FALSE) -> Food Fiesta | O17: =_xlfn.XLOOKUP(Orders!E9,Waiters!$A$2:$A$11,Waiters!$B$2:$B$11,FALSE) -> Vinod | P17: =IF(E9>=1000,"High_Sales","Normal_Sales") -> Normal_Sales | Q17: =IF(Orders!G9>=500,"Premium","Regular") -> Premium
A18: D017 | B18: 1007 | C18: M08 | D18: 2 | E18: 480 | F18: Jan | G18: 2026 | M18: =_xlfn.XLOOKUP(C10,Menu_Items!$A$2:$A$21,Menu_Items!$B$2:$B$21,"Not Found") -> Burger | N18: =_xlfn.XLOOKUP(Orders!D10,Branches!$A$2:$A$6,Branches!$B$2:$B$6,FALSE) -> Royal Dine | O18: =_xlfn.XLOOKUP(Orders!E10,Waiters!$A$2:$A$11,Waiters!$B$2:$B$11,FALSE) -> Arjun | P18: =IF(E10>=1000,"High_Sales","Normal_Sales") -> Normal_Sales | Q18: =IF(Orders!G10>=500,"Premium","Regular") -> Premium
A19: D018 | B19: 1008 | C19: M08 | D19: 1 | E19: 240 | F19: Jan | G19: 2026 | M19: =_xlfn.XLOOKUP(C11,Menu_Items!$A$2:$A$21,Menu_Items!$B$2:$B$21,"Not Found") -> French Fries | N19: =_xlfn.XLOOKUP(Orders!D11,Branches!$A$2:$A$6,Branches!$B$2:$B$6,FALSE) -> Urban Kitchen | O19: =_xlfn.XLOOKUP(Orders!E11,Waiters!$A$2:$A$11,Waiters!$B$2:$B$11,FALSE) -> Teja | P19: =IF(E11>=1000,"High_Sales","Normal_Sales") -> Normal_Sales | Q19: =IF(Orders!G11>=500,"Premium","Regular") -> Premium
A20: D019 | B20: 1008 | C20: M09 | D20: 2 | E20: 300 | F20: Jan | G20: 2026 | M20: =_xlfn.XLOOKUP(C12,Menu_Items!$A$2:$A$21,Menu_Items!$B$2:$B$21,"Not Found") -> Burger | N20: =_xlfn.XLOOKUP(Orders!D12,Branches!$A$2:$A$6,Branches!$B$2:$B$6,FALSE) -> Paradise Restaurant | O20: =_xlfn.XLOOKUP(Orders!E12,Waiters!$A$2:$A$11,Waiters!$B$2:$B$11,FALSE) -> Mahesh | P20: =IF(E12>=1000,"High_Sales","Normal_Sales") -> Normal_Sales | Q20: =IF(Orders!G12>=500,"Premium","Regular") -> Regular
A21: D020 | B21: 1008 | C21: M10 | D21: 3 | E21: 540 | F21: Jan | G21: 2026 | M21: =_xlfn.XLOOKUP(C13,Menu_Items!$A$2:$A$21,Menu_Items!$B$2:$B$21,"Not Found") -> French Fries | N21: =_xlfn.XLOOKUP(Orders!D13,Branches!$A$2:$A$6,Branches!$B$2:$B$6,FALSE) -> Spice Hub | O21: =_xlfn.XLOOKUP(Orders!E13,Waiters!$A$2:$A$11,Waiters!$B$2:$B$11,FALSE) -> Kiran | P21: =IF(E13>=1000,"High_Sales","Normal_Sales") -> Normal_Sales | Q21: =IF(Orders!G13>=500,"Premium","Regular") -> Premium
A22: D021 | B22: 1009 | C22: M09 | D22: 1 | E22: 150 | F22: Jan | G22: 2026 | M22: =_xlfn.XLOOKUP(C14,Menu_Items!$A$2:$A$21,Menu_Items!$B$2:$B$21,"Not Found") -> French Fries | N22: =_xlfn.XLOOKUP(Orders!D14,Branches!$A$2:$A$6,Branches!$B$2:$B$6,FALSE) -> Food Fiesta | O22: =_xlfn.XLOOKUP(Orders!E14,Waiters!$A$2:$A$11,Waiters!$B$2:$B$11,FALSE) -> Ramesh | P22: =IF(E14>=1000,"High_Sales","Normal_Sales") -> Normal_Sales | Q22: =IF(Orders!G14>=500,"Premium","Regular") -> Premium
... A112: D111 | B112: 1045 | C112: M05 | D112: 1 | E112: 180 | F112: Jan | G112: 2026 | M112: =_xlfn.XLOOKUP(C104,Menu_Items!$A$2:$A$21,Menu_Items!$B$2:$B$21,"Not Found") -> Chicken Biryani | N112: =_xlfn.XLOOKUP(Orders!D104,Branches!$A$2:$A$6,Branches!$B$2:$B$6,FALSE) -> FALSE | O112: =_xlfn.XLOOKUP(Orders!E104,Waiters!$A$2:$A$11,Waiters!$B$2:$B$11,FALSE) -> FALSE | P112: =IF(E104>=1000,"High_Sales","Normal_Sales") -> Normal_Sales | Q112: =IF(Orders!G104>=500,"Premium","Regular") -> Regular
A113: D112 | B113: 1045 | C113: M06 | D113: 2 | E113: 240 | F113: Jan | G113: 2026 | M113: =_xlfn.XLOOKUP(C105,Menu_Items!$A$2:$A$21,Menu_Items!$B$2:$B$21,"Not Found") -> Paneer Butter Masala | P113: =IF(E105>=1000,"High_Sales","Normal_Sales") -> Normal_Sales | Q113: =IF(Orders!G105>=500,"Premium","Regular") -> Regular
A114: D113 | B114: 1046 | C114: M06 | D114: 1 | E114: 120 | F114: Jan | G114: 2026 | M114: =_xlfn.XLOOKUP(C106,Menu_Items!$A$2:$A$21,Menu_Items!$B$2:$B$21,"Not Found") -> Pizza | P114: =IF(E106>=1000,"High_Sales","Normal_Sales") -> High_Sales | Q114: =IF(Orders!G106>=500,"Premium","Regular") -> Regular
A115: D114 | B115: 1046 | C115: M07 | D115: 2 | E115: 440 | F115: Jan | G115: 2026 | M115: =_xlfn.XLOOKUP(C107,Menu_Items!$A$2:$A$21,Menu_Items!$B$2:$B$21,"Not Found") -> Paneer Butter Masala | P115: =IF(E107>=1000,"High_Sales","Normal_Sales") -> Normal_Sales | Q115: =IF(Orders!G107>=500,"Premium","Regular") -> Regular
A116: D115 | B116: 1046 | C116: M08 | D116: 3 | E116: 720 | F116: Feb | G116: 2026 | M116: =_xlfn.XLOOKUP(C108,Menu_Items!$A$2:$A$21,Menu_Items!$B$2:$B$21,"Not Found") -> Pizza | P116: =IF(E108>=1000,"High_Sales","Normal_Sales") -> Normal_Sales | Q116: =IF(Orders!G108>=500,"Premium","Regular") -> Regular
A117: D116 | B117: 1047 | C117: M07 | D117: 1 | E117: 220 | F117: Jan | G117: 2026 | M117: =_xlfn.XLOOKUP(C109,Menu_Items!$A$2:$A$21,Menu_Items!$B$2:$B$21,"Not Found") -> Pizza | P117: =IF(E109>=1000,"High_Sales","Normal_Sales") -> Normal_Sales | Q117: =IF(Orders!G109>=500,"Premium","Regular") -> Regular
A118: D117 | B118: 1047 | C118: M08 | D118: 2 | E118: 480 | F118: Jan | G118: 2026 | M118: =_xlfn.XLOOKUP(C110,Menu_Items!$A$2:$A$21,Menu_Items!$B$2:$B$21,"Not Found") -> Burger | P118: =IF(E110>=1000,"High_Sales","Normal_Sales") -> Normal_Sales | Q118: =IF(Orders!G110>=500,"Premium","Regular") -> Regular
A119: D118 | B119: 1048 | C119: M08 | D119: 1 | E119: 240 | F119: Jan | G119: 2026 | M119: =_xlfn.XLOOKUP(C111,Menu_Items!$A$2:$A$21,Menu_Items!$B$2:$B$21,"Not Found") -> French Fries | P119: =IF(E111>=1000,"High_Sales","Normal_Sales") -> Normal_Sales | Q119: =IF(Orders!G111>=500,"Premium","Regular") -> Regular
A120: D119 | B120: 1048 | C120: M09 | D120: 2 | E120: 300 | F120: Jan | G120: 2026 | M120: =_xlfn.XLOOKUP(C112,Menu_Items!$A$2:$A$21,Menu_Items!$B$2:$B$21,"Not Found") -> Burger | P120: =IF(E112>=1000,"High_Sales","Normal_Sales") -> Normal_Sales | Q120: =IF(Orders!G112>=500,"Premium","Regular") -> Regular
A121: D120 | B121: 1048 | C121: M10 | D121: 3 | E121: 540 | F121: Jan | G121: 2026 | M121: =_xlfn.XLOOKUP(C113,Menu_Items!$A$2:$A$21,Menu_Items!$B$2:$B$21,"Not Found") -> French Fries | P121: =IF(E113>=1000,"High_Sales","Normal_Sales") -> Normal_Sales | Q121: =IF(Orders!G113>=500,"Premium","Regular") -> Regular
A122: D121 | B122: 1049 | C122: M09 | D122: 1 | E122: 150 | F122: Jan | G122: 2026 | M122: =_xlfn.XLOOKUP(C114,Menu_Items!$A$2:$A$21,Menu_Items!$B$2:$B$21,"Not Found") -> French Fries | P122: =IF(E114>=1000,"High_Sales","Normal_Sales") -> Normal_Sales | Q122: =IF(Orders!G114>=500,"Premium","Regular") -> Regular
A123: D122 | B123: 1049 | C123: M10 | D123: 2 | E123: 360 | F123: Jan | G123: 2026 | M123: =_xlfn.XLOOKUP(C115,Menu_Items!$A$2:$A$21,Menu_Items!$B$2:$B$21,"Not Found") -> Noodles | P123: =IF(E115>=1000,"High_Sales","Normal_Sales") -> Normal_Sales | Q123: =IF(Orders!G115>=500,"Premium","Regular") -> Regular
A124: D123 | B124: 1050 | C124: M10 | D124: 1 | E124: 180 | F124: Jan | G124: 2026 | M124: =_xlfn.XLOOKUP(C116,Menu_Items!$A$2:$A$21,Menu_Items!$B$2:$B$21,"Not Found") -> Fried Rice | P124: =IF(E116>=1000,"High_Sales","Normal_Sales") -> Normal_Sales | Q124: =IF(Orders!G116>=500,"Premium","Regular") -> Regular
... A251: D250 | B251: 1100 | C251: M02 | D251: 3 | E251: 1050 | F251: Jan | G251: 2026 | M251: =_xlfn.XLOOKUP(C243,Menu_Items!$A$2:$A$21,Menu_Items!$B$2:$B$21,"Not Found") -> Soup | P251: =IF(E243>=1000,"High_Sales","Normal_Sales") -> Normal_Sales | Q251: =IF(Orders!G243>=500,"Premium","Regular") -> Regular
M252: =_xlfn.XLOOKUP(C244,Menu_Items!$A$2:$A$21,Menu_Items!$B$2:$B$21,"Not Found") -> Soup | P252: =IF(E244>=1000,"High_Sales","Normal_Sales") -> Normal_Sales | Q252: =IF(Orders!G244>=500,"Premium","Regular") -> Regular
M253: =_xlfn.XLOOKUP(C245,Menu_Items!$A$2:$A$21,Menu_Items!$B$2:$B$21,"Not Found") -> Sandwich | P253: =IF(E245>=1000,"High_Sales","Normal_Sales") -> Normal_Sales | Q253: =IF(Orders!G245>=500,"Premium","Regular") -> Regular
M254: =_xlfn.XLOOKUP(C246,Menu_Items!$A$2:$A$21,Menu_Items!$B$2:$B$21,"Not Found") -> Pasta | P254: =IF(E246>=1000,"High_Sales","Normal_Sales") -> Normal_Sales | Q254: =IF(Orders!G246>=500,"Premium","Regular") -> Regular
M255: =_xlfn.XLOOKUP(C247,Menu_Items!$A$2:$A$21,Menu_Items!$B$2:$B$21,"Not Found") -> Sandwich | P255: =IF(E247>=1000,"High_Sales","Normal_Sales") -> Normal_Sales | Q255: =IF(Orders!G247>=500,"Premium","Regular") -> Regular
...

Sheet Branches
A1: Branch_ID | B1: Branch_Name | C1: City
A2: B01 | B2: Paradise Restaurant | C2: Hyderabad
A3: B02 | B3: Spice Hub | C3: Vijayawada
A4: B03 | B4: Food Fiesta | C4: Visakhapatnam
A5: B04 | B5: Royal Dine | C5: Warangal
A6: B05 | B6: Urban Kitchen | C6: Tirupati

Sheet Orders
A1: Order_ID | B1: Customer_Name | C1: Order_Date | D1: Branch_ID | E1: Waiter_ID | F1: Payment_ID | G1: Total_Amount | H1: Dining_Type
A2: 1001 | B2: Ravi | C2: 46023 | D2: B01 | E2: W01 | F2: P01 | G2: 400 | H2: Dine-In
A3: 1002 | B3: Sneha | C3: 46024 | D3: B02 | E3: W02 | F3: P02 | G3: 520 | H3: Takeaway
A4: 1003 | B4: Arjun | C4: 46025 | D4: B03 | E4: W03 | F4: P03 | G4: 640 | H4: Delivery
A5: 1004 | B5: Priya | C5: 46026 | D5: B04 | E5: W04 | F5: P04 | G5: 760 | H5: Dine-In
A6: 1005 | B6: Karthik | C6: 46027 | D6: B05 | E6: W05 | F6: P01 | G6: 880 | H6: Takeaway
A7: 1006 | B7: Teja | C7: 46028 | D7: B01 | E7: W06 | F7: P02 | G7: 1000 | H7: Delivery
A8: 1007 | B8: Anusha | C8: 46029 | D8: B02 | E8: W07 | F8: P03 | G8: 1120 | H8: Dine-In
A9: 1008 | B9: Rohit | C9: 46030 | D9: B03 | E9: W08 | F9: P04 | G9: 1240 | H9: Takeaway
A10: 1009 | B10: Pooja | C10: 46031 | D10: B04 | E10: W09 | F10: P01 | G10: 1360 | H10: Delivery
A11: 1010 | B11: Harsha | C11: 46032 | D11: B05 | E11: W10 | F11: P02 | G11: 1480 | H11: Dine-In
A12: 1011 | B12: Deepika | C12: 46033 | D12: B01 | E12: W01 | F12: P03 | G12: 400 | H12: Takeaway
A13: 1012 | B13: Sandeep | C13: 46034 | D13: B02 | E13: W02 | F13: P04 | G13: 520 | H13: Delivery
... A101: 1100 | B101: Chaitanya | C101: 46032 | D101: B05 | E101: W10 | F101: P04 | G101: 1480 | H101: Dine-In

Sheet Waiters
A1: Waiter_ID | B1: Waiter_Name | C1: Experience_Years | D1: Shift
A2: W01 | B2: Mahesh | C2: 5 | D2: Morning
A3: W02 | B3: Kiran | C3: 3 | D3: Evening
A4: W03 | B4: Ramesh | C4: 6 | D4: Morning
A5: W04 | B5: Praveen | C5: 2 | D5: Evening
A6: W05 | B6: Suresh | C6: 4 | D6: Morning
A7: W06 | B7: Naveen | C7: 1 | D7: Evening
A8: W07 | B8: Ajay | C8: 7 | D8: Morning
A9: W08 | B9: Vinod | C9: 3 | D9: Evening
A10: W09 | B10: Arjun | C10: 5 | D10: Morning
A11: W10 | B11: Teja | C11: 2 | D11: Evening

Sheet Payments
A1: Payment_ID | B1: Payment_Method
A2: P01 | B2: Cash
A3: P02 | B3: UPI
A4: P03 | B4: Credit Card
A5: P04 | B5: Debit Card

Sheet Menu_Items
A1: Item_ID | B1: Item_Name | C1: Category | D1: Price
A2: M01 | B2: Veg Biryani | C2: Main Course | D2: 250
A3: M02 | B3: Chicken Biryani | C3: Main Course | D3: 350
A4: M03 | B4: Paneer Butter Masala | C4: Main Course | D4: 280
A5: M04 | B5: Pizza | C5: Fast Food | D5: 450
A6: M05 | B6: Burger | C6: Fast Food | D6: 180
A7: M06 | B7: French Fries | C7: Snacks | D7: 120
A8: M07 | B8: Noodles | C8: Fast Food | D8: 220
A9: M08 | B9: Fried Rice | C9: Main Course | D9: 240
A10: M09 | B10: Ice Cream | C10: Dessert | D10: 150
A11: M10 | B11: Brownie | C11: Dessert | D11: 180
A12: M11 | B12: Gulab Jamun | C12: Dessert | D12: 100
A13: M12 | B13: Coke | C13: Beverage | D13: 60
... A21: M20 | B21: Pasta | C21: Fast Food | D21: 260

Sheet Povite table
A1: Branch Name | B1: Total Sales_Amount | H1: TYPE | I1: Sum of Sales_Amount
A2: Food Fiesta | B2: 18400 | H2: Delivery | I2: 28810
A3: Paradise Restaurant | B3: 18350 | H3: Dine-In | I3: 30950
A4: Royal Dine | B4: 17050 | H4: Takeaway | I4: 30690
A5: Spice Hub | B5: 19500 | H5: Grand Total | I5: 90450
A6: Urban Kitchen | B6: 17150
A7: Grand Total | B7: 90450
A11: Category | B11: Total Sales_Amount | H11: Payment Mode | I11: Sales_Amount
A12: Beverage | B12: 5700 | H12: Cash | I12: 13100
A13: Dessert | B13: 9150 | H13: Credit Card | I13: 17050
A14: Fast Food | B14: 27300 | H14: Debit Card | I14: 28500
A15: Main Course | B15: 25650 | H15: UPI | I15: 31800
A16: Snacks | B16: 5850 | H16: Grand Total | I16: 90450
A17: Starter | B17: 16800
A18: Grand Total | B18: 90450
A23: Waiter Names | B23: Total Sales_Amount | H23: Months | I23: Total Sales_Amount
A24: Ajay | B24: 6100 | H24: Jan | I24: 84640
A25: Arjun | B25: 5900 | H25: Feb | I25: 2040
A26: Kiran | B26: 13400 | H26: Mar | I26: 2170
A27: Mahesh | B27: 5850 | H27: Apr | I27: 1600
A28: Naveen | B28: 12500 | H28: Grand Total | I28: 90450
A29: Praveen | B29: 11150
A30: Ramesh | B30: 7000
A31: Suresh | B31: 5300
A32: Teja | B32: 11850
A33: Vinod | B33: 11400
A34: Grand Total | B34: 90450
A42: Total Orders | B42: Total Quntity sold | C42: Unique orders | D42: Total Sales
A43: 250 | B43: 450 | C43: 100 | D43: 90450

Sheet Dashboard
